<?xml version="1.0"?>
<robot xmlns:xacro="http://www.ros.org/wiki/xacro" name="gantry_robot">
  <xacro:macro name="gantry_robot">
  
  <material name="grey">
    <color rgba="0.7 0.7 0.7 1.0" />
  </material>

  <!-- link name="world" / -->

  <!-- IPM (Imaginary Point Marker) - 参考点 -->
  <link name="ipm">
    <visual>
      <origin xyz="0 0 0" rpy="0 0 0" />
      <geometry>
        <sphere radius="0.01" />
      </geometry>
      <material name="marker-material">
        <color rgba="1 0 0 1" />
      </material>
    </visual>
    <inertial>
      <origin xyz="0 0 0" rpy="0 0 0" />
      <mass value="0.01" />
      <inertia ixx="0.0001" ixy="0" ixz="0" iyy="0.0001" iyz="0" izz="0.0001" />
    </inertial>
  </link>

  <joint name="world_to_ipm" type="fixed">
    <parent link="world" />
    <child link="ipm" />
    <origin xyz="0.4 -0.2 0.6" rpy="1.57 0 -1.57" />
  </joint>

  <link name="link1">
    <visual>
      <origin xyz="0 0 0" rpy="0 0 0" />
      <geometry>
        <mesh filename="package://models/meshes/link1.STL" scale="0.001 0.001 0.001" />
      </geometry>
      <material name="grey" />
    </visual>
    <collision>
      <origin xyz="0 0 0" rpy="0 0 0" />
      <geometry>
        <mesh filename="package://models/meshes/link1.STL" scale="0.001 0.001 0.001" />
      </geometry>
    </collision>
    <inertial>
      <mass value="1.0" />
      <inertia ixx="0.1" ixy="0.0" ixz="0.0" iyy="0.1" iyz="0.0" izz="0.1" />
    </inertial>
  </link>

  <joint name="world_to_link1" type="fixed">
    <parent link="world" />
    <child link="link1" />
    <origin xyz="0 0 0.35" rpy="0 0 0" />
  </joint>

  <link name="link2">
    <visual>
      <origin xyz="0 0 0" rpy="0 0 0" />
      <geometry>
        <mesh filename="package://models/meshes/link2.STL" scale="0.001 0.001 0.001" />
      </geometry>
      <material name="grey" />
    </visual>
    <collision>
      <origin xyz="0 0 0" rpy="0 0 0" />
      <geometry>
        <mesh filename="package://models/meshes/link2.STL" scale="0.001 0.001 0.001" />
      </geometry>
    </collision>
    <inertial>
      <mass value="1.0" />
      <inertia ixx="0.1" ixy="0.0" ixz="0.0" iyy="0.1" iyz="0.0" izz="0.1" />
    </inertial>
  </link>

  <joint name="joint_1_2" type="prismatic">
    <parent link="link1" />
    <child link="link2" />
    <origin xyz="0.1 0 0.2" rpy="0 0 0" />
    <axis xyz="0 0 1"/>
    <limit lower="-0.3" upper="0.1" velocity="0.5" effort="1000"/>
  </joint>

  <link name="link3">
    <visual>
      <origin xyz="0 0 0" rpy="0 0 0" />
      <geometry>
        <mesh filename="package://models/meshes/link3.STL" scale="0.001 0.001 0.001" />
      </geometry>
      <material name="grey" />
    </visual>
    <collision>
      <origin xyz="0 0 0" rpy="0 0 0" />
      <geometry>
        <mesh filename="package://models/meshes/link3.STL" scale="0.001 0.001 0.001" />
      </geometry>
    </collision>
    <inertial>
      <mass value="1.0" />
      <inertia ixx="0.1" ixy="0.0" ixz="0.0" iyy="0.1" iyz="0.0" izz="0.1" />
    </inertial>
  </link>

  <joint name="joint_2_3" type="revolute">
    <parent link="link2" />
    <child link="link3" />
    <origin xyz="0.141 -0.2 0" rpy="0 1.57 0" />
    <axis xyz="0 0 1"/>
    <limit lower="0" upper="6.28" effort="1000" velocity="1.0"/>
  </joint>

  <link name="link4">
    <visual>
      <origin xyz="-0.063 0.04 0" rpy="0 0 0" />
      <geometry>
        <mesh filename="package://models/meshes/link4.STL" scale="0.001 0.001 0.001" />
      </geometry>
      <material name="grey" />
    </visual>
    <collision>
      <origin xyz="-0.063 0.04 0" rpy="0 0 0" />
      <geometry>
        <mesh filename="package://models/meshes/link4.STL" scale="0.001 0.001 0.001" />
      </geometry>
    </collision>
    <inertial>
      <mass value="1.0" />
      <inertia ixx="0.1" ixy="0.0" ixz="0.0" iyy="0.1" iyz="0.0" izz="0.1" />
    </inertial>
  </link>

  <joint name="joint_3_4" type="revolute">
    <parent link="link3" />
    <child link="link4" />
    <origin xyz="0 0 0.03" rpy="-1.57 1.57 0" />
    <axis xyz="0 0 1"/>
    <limit lower="0" upper="3.14" effort="1000" velocity="1.0"/>
  </joint>

  <link name="link5">
    <visual>
      <origin xyz="0 0 0" rpy="0 0 0" />
      <geometry>
        <mesh filename="package://models/meshes/link5.STL" scale="0.001 0.001 0.001" />
      </geometry>
      <material name="grey" />
    </visual>
    <collision>
      <origin xyz="0 0 0" rpy="0 0 0" />
      <geometry>
        <mesh filename="package://models/meshes/link5.STL" scale="0.001 0.001 0.001" />
      </geometry>
    </collision>
    <inertial>
      <mass value="1.0" />
      <inertia ixx="0.1" ixy="0.0" ixz="0.0" iyy="0.1" iyz="0.0" izz="0.1" />
    </inertial>
  </link>

  <joint name="joint_4_5" type="revolute">
    <parent link="link4" />
    <child link="link5" />
    <origin xyz="-0.226 0.06557 0" rpy="0 1.57 1.57" />
    <axis xyz="0 1 0"/>
    <limit lower="-3.14" upper="3.14" effort="1000" velocity="1.0"/>
  </joint>

  <link name="link6">
    <visual>
      <origin xyz="-0.03 0.034 0" rpy="0 0 0" />
      <geometry>
        <mesh filename="package://models/meshes/link6.STL" scale="0.001 0.001 0.001" />
      </geometry>
      <material name="grey" />
    </visual>
    <collision>
      <origin xyz="-0.03 0.034 0" rpy="0 0 0" />
      <geometry>
        <mesh filename="package://models/meshes/link6.STL" scale="0.001 0.001 0.001" />
      </geometry>
    </collision>
    <inertial>
      <mass value="1.0" />
      <inertia ixx="0.1" ixy="0.0" ixz="0.0" iyy="0.1" iyz="0.0" izz="0.1" />
    </inertial>
  </link>

  <joint name="joint_5_6" type="revolute">
    <parent link="link5" />
    <child link="link6" />
    <origin xyz="0 0.025 0" rpy="0 1.57 0" />
    <axis xyz="1 0 0"/>
    <limit lower="-1.57" upper="1.57" effort="1000" velocity="1.0"/>
  </joint>

  <link name="link7">
    <visual>
      <origin xyz="0 -0.0295 0" rpy="0 0 0" />
      <geometry>
        <mesh filename="package://models/meshes/link7.STL" scale="0.001 0.001 0.001" />
      </geometry>
      <material name="grey" />
    </visual>
    <collision>
      <origin xyz="0 -0.0295 0" rpy="0 0 0" />
      <geometry>
        <mesh filename="package://models/meshes/link7.STL" scale="0.001 0.001 0.001" />
      </geometry>
    </collision>
    <inertial>
      <mass value="1.0" />
      <inertia ixx="0.1" ixy="0.0" ixz="0.0" iyy="0.1" iyz="0.0" izz="0.1" />
    </inertial>
  </link>

  <joint name="joint_6_7" type="revolute">
    <parent link="link6" />
    <child link="link7" />
    <origin xyz="-0.0015 0.18 0" rpy="0 3.14 0" />
    <axis xyz="0 1 0"/>
    <limit lower="-3.14" upper="3.14" effort="1000" velocity="1.0"/>
  </joint>

  </xacro:macro>
</robot>
