<?xml version="1.0"?>
<robot xmlns:xacro="http://www.ros.org/wiki/xacro" name="stand">
  <xacro:macro name="stand">
  
  <!-- link name="world"></link -->

  <joint name="base_joint" type="fixed">
    <parent link="world" />
    <child link="bottom" />
    <origin xyz="1.632 -0.2 0.45" rpy="0 0 3.14" />
  </joint>

  <link name="ipm">
    <visual>
      <origin xyz="0 0 0" rpy="0 0 0" />
      <geometry>
        <sphere radius="0.01" />
      </geometry>
      <material name="marker-material">
        <color rgba="1 0 0 1" />
      </material>
    </visual>
    <inertial>
      <origin xyz="0 0 0" rpy="0 0 0" />
      <mass value="0.01" />
      <inertia ixx="0.0001" ixy="0" ixz="0" iyy="0.0001" iyz="0" izz="0.0001" />
    </inertial>
  </link>

  <joint name="world_to_ipm" type="fixed">
    <parent link="world" />
    <child link="ipm" />
    <origin xyz="0.4 -0.2 0.6" rpy="1.57 0 -1.57" />
  </joint>

  <link name="bottom">
    <visual>
      <origin xyz="0 0 0" rpy="0 0 0" />
      <geometry>
        <box size="0.3 0.5 0.1" />
      </geometry>
      <material name="bottom-material">
        <color rgba="0.023153366173251363 0.14412847084818123 0.8962693533719567 1" />
      </material>
    </visual>
    <collision>
      <origin xyz="0 0 0" rpy="0 0 0" />
      <geometry>
        <box size="0.5 0.8 0.1" />
      </geometry>
    </collision>
    <inertial>
      <origin xyz="0 0 0" rpy="0 0 0" />
      <mass value="1" />
      <inertia ixx="0.16666666666666666" ixy="0" ixz="0" iyy="0.16666666666666666" iyz="0" izz="0.16666666666666666" />
    </inertial>
  </link>

  <joint name="bottom_to_cube1" type="revolute">
    <parent link="bottom" />
    <child link="cube1" />
    <origin xyz="0 -0.2 0.15" rpy="0 0 0" />
    <axis xyz="0 0 1"/>
    <limit effort="1000.0" lower="-1.57" upper="1.57" velocity="0.5"/>  </joint>

  <link name="cube1">
    <visual>
      <origin xyz="0 0 0" rpy="0 0 0" />
      <geometry>
        <box size="0.2 0.2 0.2" />
      </geometry>
      <material name="cube1-material">
        <color rgba="1 0.019382360952473074 0.07818742179702069 1" />
      </material>
    </visual>
    <collision>
      <origin xyz="0 0 0" rpy="0 0 0" />
      <geometry>
        <box size="0.2 0.2 0.2" />
      </geometry>
    </collision>
    <inertial>
      <origin xyz="0 0 0" rpy="0 0 0" />
      <mass value="1" />
      <inertia ixx="0.16666666666666666" ixy="0" ixz="0" iyy="0.16666666666666666" iyz="0" izz="0.16666666666666666" />
    </inertial>
  </link>

  <joint name="cube1_to_cylinder0" type="revolute">
    <parent link="cube1" />
    <child link="cylinder0" />
    <origin xyz="0 0.125 0" rpy="-1.5707963267948963 0 0" />
    <axis xyz="0 0 1"/>
    <limit effort="1000.0" lower="-1" upper="1" velocity="0.5"/>  </joint>

  <link name="cylinder0">
    <visual>
      <origin xyz="0 0 0" rpy="0 0 0" />
      <geometry>
        <cylinder radius="0.05" length="0.05" />
      </geometry>
      <material name="cylinder0-material">
        <color rgba="0.15292615198613213 0.913098651791473 0.023153366173251363 1" />
      </material>
    </visual>
    <collision>
      <origin xyz="0 0 0" rpy="0 0 0" />
      <geometry>
        <cylinder radius="0.05" length="0.05" />
      </geometry>
    </collision>
    <inertial>
      <origin xyz="0 0 0" rpy="0 0 0" />
      <mass value="1" />
      <inertia ixx="0.3333333333333333" ixy="0" ixz="0" iyy="0.5" iyz="0" izz="0.3333333333333333" />
    </inertial>
  </link>

  <joint name="cylinder0_to_cube3" type="fixed">
    <parent link="cylinder0" />
    <child link="cube3" />
    <origin xyz="0 0 0.07499999999999994" rpy="1.5707963267948963 0 0" />
  </joint>

  <link name="cube3">
    <visual>
      <origin xyz="0 0 0" rpy="0 0 0" />
      <geometry>
        <box size="0.1 0.1 0.1" />
      </geometry>
      <material name="cube3-material">
        <color rgba="0.07421356837213867 0.407240211891531 0.21952619971859377 1" />
      </material>
    </visual>
    <collision>
      <origin xyz="0 0 0" rpy="0 0 0" />
      <geometry>
        <box size="0.1 0.1 0.1" />
      </geometry>
    </collision>
    <inertial>
      <origin xyz="0 0 0" rpy="0 0 0" />
      <mass value="1" />
      <inertia ixx="0.16666666666666666" ixy="0" ixz="0" iyy="0.16666666666666666" iyz="0" izz="0.16666666666666666" />
    </inertial>
  </link>

  <joint name="cube3_to_cylinder1" type="revolute">
    <parent link="cube3" />
    <child link="cylinder1" />
    <origin xyz="0 0 0.4" rpy="0 0 0" />
    <axis xyz="0 0 1"/>
    <limit effort="1000.0" lower="-1.57" upper="1.57" velocity="0.5"/>  </joint>

  <link name="cylinder1">
    <visual>
      <origin xyz="0 1.1102230246251575e-17 0" rpy="0 0 0" />
      <geometry>
        <cylinder radius="0.05" length="0.7" />
      </geometry>
      <material name="cylinder1-material">
        <color rgba="0.15292615198613213 0.913098651791473 0.023153366173251363 1" />
      </material>
    </visual>
    <collision>
      <origin xyz="0 1.1102230246251575e-17 0" rpy="0 0 0" />
      <geometry>
        <cylinder radius="0.05" length="0.7" />
      </geometry>
    </collision>
    <inertial>
      <origin xyz="0 1.1102230246251575e-17 0" rpy="0 0 0" />
      <mass value="1" />
      <inertia ixx="0.3333333333333333" ixy="0" ixz="0" iyy="0.5" iyz="0" izz="0.3333333333333333" />
    </inertial>
  </link>

  <joint name="cylinder1_to_cube5" type="fixed">
    <parent link="cylinder1" />
    <child link="cube5" />
    <origin xyz="0 0 0.35" rpy="0 0 0" />
  </joint>

  <link name="cube5">
    <visual>
      <origin xyz="0 0 0" rpy="0 0 0" />
      <geometry>
        <box size="0.1 0.1 0.1" />
      </geometry>
      <material name="cube5-material">
        <color rgba="0.3967552307153359 0.6938717612856897 0.623960391667596 1" />
      </material>
    </visual>
    <collision>
      <origin xyz="0 0 0" rpy="0 0 0" />
      <geometry>
        <box size="0.1 0.1 0.1" />
      </geometry>
    </collision>
    <inertial>
      <origin xyz="0 0 0" rpy="0 0 0" />
      <mass value="1" />
      <inertia ixx="0.16666666666666666" ixy="0" ixz="0" iyy="0.16666666666666666" iyz="0" izz="0.16666666666666666" />
    </inertial>
  </link>

  <joint name="cube5_to_cube6" type="revolute">
    <parent link="cube5" />
    <child link="cube6" />
    <origin xyz="0 -0.1 0" rpy="-1.5707963267948963 0 0" />
    <axis xyz="0 0 1"/>
    <limit effort="1000.0" lower="-1.57" upper="1.57" velocity="0.5"/>  </joint>

  <link name="cube6">
    <visual>
      <origin xyz="0 0 0" rpy="0 0 0" />
      <geometry>
        <box size="0.1 0.1 0.1" />
      </geometry>
      <material name="cube6-material">
        <color rgba="0.3967552307153359 0.6938717612856897 0.623960391667596 1" />
      </material>
    </visual>
    <collision>
      <origin xyz="0 0 0" rpy="0 0 0" />
      <geometry>
        <box size="0.1 0.1 0.1" />
      </geometry>
    </collision>
    <inertial>
      <origin xyz="0 0 0" rpy="0 0 0" />
      <mass value="1" />
      <inertia ixx="0.16666666666666666" ixy="0" ixz="0" iyy="0.16666666666666666" iyz="0" izz="0.16666666666666666" />
    </inertial>
  </link>

  <joint name="cube6_to_cylinder2" type="fixed">
    <parent link="cube6" />
    <child link="cylinder2" />
    <origin xyz="0.3 0 0" rpy="1.5707963267948966 2.220446049250313e-16 1.5707963267948963" />
  </joint>

  <link name="cylinder2">
    <visual>
      <origin xyz="0 0 0" rpy="0 0 0" />
      <geometry>
        <cylinder radius="0.05" length="0.5" />
      </geometry>
      <material name="cylinder2-material">
        <color rgba="0.11697066774917994 0.04231141061442144 0.6514056374127929 1" />
      </material>
    </visual>
    <collision>
      <origin xyz="0 0 0" rpy="0 0 0" />
      <geometry>
        <cylinder radius="0.05" length="0.5" />
      </geometry>
    </collision>
    <inertial>
      <origin xyz="0 0 0" rpy="0 0 0" />
      <mass value="1" />
      <inertia ixx="0.3333333333333333" ixy="0" ixz="0" iyy="0.5" iyz="0" izz="0.3333333333333333" />
    </inertial>
  </link>

  <joint name="cylinder2_to_cube7" type="fixed">
    <parent link="cylinder2" />
    <child link="cube7" />
    <origin xyz="0 0 0.3" rpy="-1.1102230246251565e-16 -1.5707963267948966 1.1102230246251568e-16" />
  </joint>

  <link name="cube7">
    <visual>
      <origin xyz="0 0 0" rpy="0 0 0" />
      <geometry>
        <box size="0.1 0.1 0.1" />
      </geometry>
      <material name="cube7-material">
        <color rgba="0.1499597898006365 0.4019777798219466 0.5028864580233624 1" />
      </material>
    </visual>
    <collision>
      <origin xyz="0 0 0" rpy="0 0 0" />
      <geometry>
        <box size="0.1 0.1 0.1" />
      </geometry>
    </collision>
    <inertial>
      <origin xyz="0 0 0" rpy="0 0 0" />
      <mass value="1" />
      <inertia ixx="0.16666666666666666" ixy="0" ixz="0" iyy="0.16666666666666666" iyz="0" izz="0.16666666666666666" />
    </inertial>
  </link>

  <joint name="cube7_to_cube8" type="revolute">
    <parent link="cube7" />
    <child link="cube8" />
    <origin xyz="0 0.1 0" rpy="-1.5707963267948963 0 -1.2154326714572542e-63" />
    <axis xyz="0 0 1"/>
    <limit effort="1000.0" lower="-1.57" upper="1.57" velocity="0.5"/>  </joint>

  <link name="cube8">
    <visual>
      <origin xyz="0 0 0" rpy="0 0 0" />
      <geometry>
        <box size="0.2 0.1 0.1" />
      </geometry>
      <material name="cube8-material">
        <color rgba="0.1499597898006365 0.4019777798219466 0.5028864580233624 1" />
      </material>
    </visual>
    <collision>
      <origin xyz="0 0 0" rpy="0 0 0" />
      <geometry>
        <box size="0.2 0.1 0.1" />
      </geometry>
    </collision>
    <inertial>
      <origin xyz="0 0 0" rpy="0 0 0" />
      <mass value="1" />
      <inertia ixx="0.16666666666666666" ixy="0" ixz="0" iyy="0.16666666666666666" iyz="0" izz="0.16666666666666666" />
    </inertial>
  </link>

  <joint name="cube8_to_cube9" type="revolute">
    <parent link="cube8" />
    <child link="cube9" />
    <origin xyz="0.125 0 0" rpy="-2.465190328815662e-32 1.5707963267948966 -2.465190328815662e-32" />
    <axis xyz="0 0 1"/>
    <limit effort="1000.0" lower="-0.7854" upper="0.7854" velocity="0.5"/>  </joint>

  <link name="cube9">
    <visual>
      <origin xyz="0 0 0" rpy="0 0 0" />
      <geometry>
        <box size="0.6 0.6 0.05" />
      </geometry>
      <material name="cube9-material">
        <color rgba="0.008568125615105716 0.3049873140591091 0.09305896283800832 1" />
      </material>
    </visual>
    <collision>
      <origin xyz="0 0 0" rpy="0 0 0" />
      <geometry>
        <box size="0.6 0.6 0.05" />
      </geometry>
    </collision>
    <inertial>
      <origin xyz="0 0 0" rpy="0 0 0" />
      <mass value="1" />
      <inertia ixx="0.16666666666666666" ixy="0" ixz="0" iyy="0.16666666666666666" iyz="0" izz="0.16666666666666666" />
    </inertial>
  </link>

  <joint name="cube9_to_cylinder3" type="fixed">
    <parent link="cube9" />
    <child link="cylinder3" />
    <origin xyz="4.336808689942018e-19 0.2085 0.0525" rpy="-2.220446049250313e-16 0 3.14159" />
  </joint>

  <link name="cylinder3">
    <visual>
      <origin xyz="0 0 0" rpy="0 0 0" />
      <geometry>
        <cylinder radius="0.018" length="0.1" />
      </geometry>
      <material name="cylinder3-material">
        <color rgba="0.76052450467022 0.16202937562896222 0.8631572134510892 1" />
      </material>
    </visual>
    <collision>
      <origin xyz="0 0 0" rpy="0 0 0" />
      <geometry>
        <cylinder radius="0.018" length="0.1" />
      </geometry>
    </collision>
    <inertial>
      <origin xyz="0 0 0" rpy="0 0 0" />
      <mass value="1" />
      <inertia ixx="0.3333333333333333" ixy="0" ixz="0" iyy="0.5" iyz="0" izz="0.3333333333333333" />
    </inertial>
  </link>

  </xacro:macro>
</robot>
